Workbook
Name AllUserNames: #REF!
Name AllUserNames: #REF!
Name AllUserNames: #REF!
Name DecisionLastCategory: '[1]Test Decision'!$P$3409
Name DecisionLastSize: '[1]Test Decision'!$Q$3409
Name QACP_Project_Setup: #REF!
Name QACP_Project_Setup: #REF!
Name QACP_Project_Setup: #REF!
Name QACPRiskFactorWeights: #REF!
Name QACPRiskFactorWeights: #REF!
Name QACPRiskFactorWeights: #REF!
Name Raw_Data_In: #REF!
Name Raw_Data_In: #REF!
Name Raw_Data_In: #REF!
Name sfsfd: [2]Users!$A$2:$A$5
Name TempUsers: #REF!
Name TempUsers: #REF!
Name TempUsers: #REF!
Name UserIDs: #REF!
Name UserIDs: #REF!
Name UserIDs: #REF!
Name UserList: #REF!
Name UserList: #REF!
Name UserList: #REF!
Name UserNames: #REF!
Name UserNames: #REF!
Name UserNames: #REF!

Sheet Copertina
A2: Il presente documento è stato redatto con la collaborazione del RTI Engineering Ingegneria Informatica S.p.A. & Sirfin-PA S.r.l. nell’ambito del contratto CIG 73479643B7 per lo “Sviluppo del Sistema Informativo Unitario Telematico, la manutenzione degli attuali sistemi dell’area Penale del Ministero della Giustizia e servizi correlati. Lotto 1”.
A3: Nome del file | B3: SIUT-SIES-CT-1.0-20230327-Allegato_al_piano_Test_2023_13_PST_PagoPA
A4: Piano di test | B4: SIUT-SIES-PT-1.0-20230327-Piano_dei_Test_2023_13_PST_PagoPA
A5: Versione | B5: 1.0
A6: Data | B6: 45012
A7: Intervento | B7: MEV 2023_13_PST_PagoPA
A8: Area Applicativa | B8: Penale
A9: Allegato al Piano dei Test

Sheet TabellaTest
A1: Intervento | C1: =Copertina!B7 -> MEV 2023_13_PST_PagoPA
A2: Codifica Piano di test | C2: =Copertina!B3 -> SIUT-SIES-CT-1.0-20230327-Allegato_al_piano_Test_2023_13_PST_PagoPA
A3: Codice Appl. | B3: ID. Requisito Padre | C3: Lista Requisiti | D3: ID Caso d'uso | E3: Caso d'uso | F3: ID | G3: Scenario di test | H3: Classe di Gravità (1-4) | I3: Classe di rilevanza (A, B, C) | J3: Esito
A4: SIES | B4: PAR. 2.2-013-01 | C4: PAR. 2.2-013-01 | D4: UC01 | E4: Verifica inserimento pena complessiva in SIEP | F4: TF001.UC01 | G4: Verifica: Verificare che nel sottosistema SIEP nella iscrizione della pena complessiva siaano gestite le Pene Sostitutive delle Pene Detentive Brevi | H4: 3 | I4: C
A5: SIES | B5: PAR. 2.2-013-01 | C5: PAR. 2.2-013-01 | D5: UC02 | E5: Verifica modifica pena complessiva in SIEP | F5: TF001.UC02 | G5: Verifica: Verificare che nel sottosistema SIEP nella modifica della pena complessiva siaano gestite le Pene Sostitutive delle Pene Detentive Brevi | H5: 3 | I5: C
A6: SIES | B6: PAR. 2.1-013-01 | C6: PAR. 2.2-013-01 | D6: UC03 | E6: Verifica cancellazione pena complessiva in SIEP | F6: TF001.UC03 | G6: Verifica: Verificare che nel sottosistema SIEP nella cancellazione della pena complessiva siaano gestite le Pene Sostitutive delle Pene Detentive Brevi | H6: 3 | I6: C
A7: SIES | B7: PAR. 2.3-013-01 | C7: PAR. 2.3-013-01 | D7: UC01 | E7: Verifica inserimento modalità di pagamento pena pecuniaria in SIEP | F7: TF002.UC01 | G7: Verifica: Verificare nel sottosistema SIEP l'utilizzo della funzione inserimento modalità di pagamento pena pecuniaria | H7: 2 | I7: B
A8: SIES | B8: PAR. 2.3-013-01 | C8: PAR. 2.3-013-01 | D8: UC02 | E8: Verifica modifica modalità di pagamento pena pecuniaria in SIEP | F8: TF002.UC02 | G8: Verifica: Verificare nel sottosistema SIEP l'utilizzo della funzione modifica modalità di pagamento pena pecuniaria | H8: 2 | I8: B
A9: SIES | B9: PAR. 2.3-013-01 | C9: PAR. 2.3-013-01 | D9: UC03 | E9: Verifica cancellazione modalità di pagamento pena pecuniaria in SIEP | F9: TF002.UC03 | G9: Verifica: Verificare nel sottosistema SIEP l'utilizzo della funzione cancellazione modalità di pagamento pena pecuniaria | H9: 2 | I9: B
A10: SIES | B10: PAR. 2.4-013-01 | C10: PAR. 2.4-013-01 | D10: UC01 | E10: Verifica inserimento Civilmente Obbligato per la pena pecuniaria in SIEP (persona fisica) | F10: TF003.UC01 | G10: Verifica: Verificare nel sottosistema SIEP l'utilizzo della funzione inserimento Civilmente Obbligato per la pena pecuniaria (persona fisica) | H10: 2 | I10: B
A11: SIES | B11: PAR. 2.4-013-01 | C11: PAR. 2.4-013-01 | D11: UC02 | E11: Verifica modifica Civilmente Obbligato per la pena pecuniaria in SIEP (persona fisica) | F11: TF003.UC02 | G11: Verifica: Verificare nel sottosistema SIEP l'utilizzo della funzione modifica Civilmente Obbligato per la pena pecuniaria (persona fisica) | H11: 2 | I11: B
A12: SIES | B12: PAR. 2.4-013-01 | C12: PAR. 2.4-013-01 | D12: UC03 | E12: Verifica cancellazione Civilmente Obbligato per la pena pecuniaria in SIEP (persona fisica) | F12: TF003.UC03 | G12: Verifica: Verificare nel sottosistema SIEP l'utilizzo della funzione cancellazione Civilmente Obbligato per la pena pecuniaria (persona fisica) | H12: 2 | I12: B
A13: SIES | B13: PAR. 2.4-013-01 | C13: PAR. 2.4-013-01 | D13: UC04 | E13: Verifica inserimento Civilmente Obbligato per la pena pecuniaria in SIEP (persona giuridica) | F13: TF003.UC04 | G13: Verifica: Verificare nel sottosistema SIEP l'utilizzo della funzione inserimento Civilmente Obbligato per la pena pecuniaria (persona giuridica) | H13: 2 | I13: B
A14: SIES | B14: PAR. 2.5.1-013-01 | C14: PAR. 2.5.1-013-01 | D14: UC01 | E14: Verifica inserimento Ordine Ingiunzione al Pagamento pena pecuniaria in SIEP | F14: TF004.UC01 | G14: Verifica: Verificare nel sottosistema SIEP l'utilizzo della funzione inserimento Ordine Ingiunzione al Pagamento pena pecuniaria | H14: 2 | I14: B
A15: SIES | B15: PAR. 2.5.1-013-01 | C15: PAR. 2.5.1-013-01 | D15: UC02 | E15: Verifica modifica Ordine Ingiunzione al Pagamento pena pecuniaria in SIEP | F15: TF004.UC02 | G15: Verifica: Verificare nel sottosistema SIEP l'utilizzo della funzione modifica Ordine Ingiunzione al Pagamento pena pecuniaria | H15: 2 | I15: B
... A24: SIES | B24: PAR. 2.7.3-013-01 | C24: PAR. 2.7.3-013-01 | D24: UC01 | E24: Verifica funzione Batch Di Verifica Stato Del Pagamento | F24: TF009.UC01 | G24: Verifica: Verificare nel sottosistema SIEP l'utilizzo della funzione Batch Di Verifica Stato Del Pagamento | H24: 2 | I24: B

Sheet SpecificaTest
A1: Intervento | D1: =Copertina!B7 -> MEV 2023_13_PST_PagoPA
A2: Codifica Piano di test | D2: =Copertina!B3 -> SIUT-SIES-CT-1.0-20230327-Allegato_al_piano_Test_2023_13_PST_PagoPA
A3: ID caso di test | B3: Requisito | D3: Caso d'uso | F3: Scenario di test
A4: =TabellaTest!F4 -> TF001.UC01 | B4: =TabellaTest!C4 -> PAR. 2.2-013-01 | D4: =TabellaTest!E4 -> Verifica inserimento pena complessiva in SIEP | F4: =TabellaTest!G4 -> Verifica: Verificare che nel sottosistema SIEP nella iscrizione della pena complessiva siaano gestite le Pene Sostitutive delle Pene Detentive Brevi
B5: Step | C5: Tipo | D5: Istruzioni (test) | E5: Dati di input (Associated Data) | F5: Risultati attesi (Expected Result) | G5: Esito
B6: P | C6: Attività Preliminari e/o Precondizioni | D6: L'utente effettua l'accesso al sistema SIEP come Procura della Repubblica c/o Tribunale Ordinario | E6: Axxxxx (Procura della Repubblica c/o Tribunale Ordinario)
B7: P | C7: Stato Base | D7: L'utente si trova nella pagina di Dettaglio di un Procedimento in stato di Iscritto privo della pena complessiva
B8: 1 | C8: Navigazione | D8: Nella toolbar delle funzioni, seleziona Iscrizione Pena Complessiva e Icona "Vai" | F8: Visualizzazione pagina Inserimento Pena Complessiva
B9: V | C9: Verifica | D9: Verificare che sia presente la sezione relativa all'iscrizione delle Pene Sostitutive delle Pene Detentive Brevi | G9: OK
B10: 2 | C10: Azione | D10: Cliccare alternativamente sui Check box di Sanzione Sostitutiva e Pene Sostituve | F10: nella form si abilitano alternativamente per la digitazione i campi relativi al check box selezionato
B11: V | C11: Verifica | D11: Verificare che nella combo box Tipo di Pene Sostitutive siano presenti le seguenti voci: -, Detenzione Domiciliare Sostitutiva, Lavoro Pubblica Utilità Sostitutivo, Pena Pecuniaria Sostitutiva, Semilibertà Sostitutiva | G11: OK
B12: 3 | C12: Azione | D12: Compilare almeno un campo della Pena, i campi della Pena Sostitutiva e Confermare | F12: Visualizzazione form Dettaglio Pena Complessiva
B13: V | C13: Verifica | D13: Verificare che nella form: siano riportati i campi valorizzati, conformi a quelli digitati al passo precedente; accanto all'intestazione della form siano presenti le icone di Modifica e Cancellazione; nella toolbar delle funzioni siano presenti le voci Modalità Pagamento Pena Pecuniaria, Civilmente Obbligato per la Pena Pecuniaria, Ulteriori Sentenze in continuazione | G13: OK
B14: 5 | C14: Azione | D14: Cliccare su Anno e Numero Procedimento | F14: Visualizzazione form Dettaglio Procedimento
B15: V | C15: Verifica | D15: Verificare che nella form visualizzata siano riportate correttamente le tipologie ed i quantum relativi alla Pena e alla Pena sostitutiva | G15: OK
A16: =TabellaTest!F5 -> TF001.UC02 | B16: =TabellaTest!C5 -> PAR. 2.2-013-01 | D16: =TabellaTest!E5 -> Verifica modifica pena complessiva in SIEP | F16: =TabellaTest!G5 -> Verifica: Verificare che nel sottosistema SIEP nella modifica della pena complessiva siaano gestite le Pene Sostitutive delle Pene Detentive Brevi
B17: Step | C17: Tipo | D17: Istruzioni (test) | E17: Dati di input (Associated Data) | F17: Risultati attesi (Expected Result) | G17: Esito
B18: P | C18: Attività Preliminari e/o Precondizioni | D18: L'utente effettua l'accesso al sistema SIEP come Procura della Repubblica c/o Tribunale Ordinario | E18: Axxxxx (Procura della Repubblica c/o Tribunale Ordinario)
B19: P | C19: Stato Base | D19: L'utente si trova nella pagina di Dettaglio di un Procedimento di cui al precedente Test
B20: 1 | C20: Navigazione | D20: Nella toolbar delle funzioni, selezionare Dettaglio Pena Complessiva e Icona "Vai" | F20: Visualizzazione pagina Dettaglio Pena Complessiva
B21: 2 | C21: Azione | D21: Cliccare sull'icona di Modifica | F21: Visualizzazione pagina Modifica Pena Complessiva e sentenze in Continuazione
B22: V | C22: Verifica | D22: Verificare che siano riportati i quantum della pena principale (detentiva e pecuniaria) e quelli della pena sostitutiva | G22: OK
B23: 3 | C23: Azione | D23: Cliccare sull'icona di Modifica della Pena Complessiva | F23: Visualizzazione pagina Modifica Pena Complessiva
B24: V | C24: Verifica | D24: Verificare che sia presente la sezione relativa alla modifica delle Pene Sostitutive delle Pene Detentive Brevi e che siano riportati tutti i quantum relativi alla pena complessiva | G24: OK
B25: 4 | C25: Azione | D25: Modificare i dati di interesse e Confermare | F25: Visualizzazione pagina Dettaglio Pena Complessiva
B26: V | C26: Verifica | D26: Verificare che nella form i dati riportati corrispondano a quelli modificati | G26: OK
A27: =TabellaTest!F6 -> TF001.UC03 | B27: =TabellaTest!C6 -> PAR. 2.2-013-01 | D27: =TabellaTest!E6 -> Verifica cancellazione pena complessiva in SIEP | F27: =TabellaTest!G6 -> Verifica: Verificare che nel sottosistema SIEP nella cancellazione della pena complessiva siaano gestite le Pene Sostitutive delle Pene Detentive Brevi
B28: Step | C28: Tipo | D28: Istruzioni (test) | E28: Dati di input (Associated Data) | F28: Risultati attesi (Expected Result) | G28: Esito
B29: P | C29: Attività Preliminari e/o Precondizioni | D29: L'utente effettua l'accesso al sistema SIEP come Procura della Repubblica c/o Tribunale Ordinario | E29: Axxxxx (Procura della Repubblica c/o Tribunale Ordinario)
B30: P | C30: Stato Base | D30: L'utente si trova nella pagina di Dettaglio della Pena Complessiva del procedimento di cui al precedente Test
B31: 1 | C31: Azione | D31: Cliccare sull'icona di Cancellazione | F31: Visualizzazione pagina Cancella Pena Complessiva
B32: V | C32: Verifica | D32: Verificare che siano riportati i quantum della pena principale (detentiva e pecuniaria) e quelli della pena sostitutiva | G32: OK
B33: 2 | C33: Azione | D33: Cliccare sull'icona di Cancellazione | F33: Visualizzazione messaggio con richiesta autorizzazione a procedere
B34: 3 | C34: Azione | D34: cliccare su OK | F34: Visualizzazione pagina Dettaglio Procedimento
B35: V | C35: Verifica | D35: Verificare che nella form visualizzata non siano presenti i dati della pena e della pena sostitutiva | G35: OK
A36: =TabellaTest!F7 -> TF002.UC01 | B36: =TabellaTest!C7 -> PAR. 2.3-013-01 | D36: =TabellaTest!E7 -> Verifica inserimento modalità di pagamento pena pecuniaria in SIEP | F36: =TabellaTest!G7 -> Verifica: Verificare nel sottosistema SIEP l'utilizzo della funzione inserimento modalità di pagamento pena pecuniaria
B37: Step | C37: Tipo | D37: Istruzioni (test) | E37: Dati di input (Associated Data) | F37: Risultati attesi (Expected Result) | G37: Esito
B38: P | C38: Attività Preliminari e/o Precondizioni | D38: L'utente effettua l'accesso al sistema SIEP come Procura della Repubblica c/o Tribunale Ordinario | E38: Axxxxx (Procura della Repubblica c/o Tribunale Ordinario)
B39: P | C39: Stato Base | D39: L'utente si trova nella pagina di Dettaglio della Pena Complessiva di un procedimento in stato di iscritto (eventualmente ripetere test TF001.UC01)
B40: 1 | C40: Navigazione | D40: Nella toolbar delle funzioni, selezionare Modalità Pagamento Pena Pecuniaria e Icona "Vai" | F40: Visualizzazione pagina Inserimento Modalità Pagamento Pena Pecuniaria
...

Sheet VerificheConformità
A1: Intervento | D1: =Copertina!B7 -> MEV 2023_13_PST_PagoPA
A2: Codifica Piano di test | D2: =Copertina!B3 -> SIUT-SIES-CT-1.0-20230327-Allegato_al_piano_Test_2023_13_PST_PagoPA
A3: ID | B3: Tipo Verifica | C3: Attributo | D3: Indicatore | E3: Descrizione tipo Verifica | F3: Esito Verifica Fornitore | G3: Esito Verifica Amministrazione
A4: 001 | B4: Adeguatezza delle funzionalità | C4: Completezza funzionale | D4: Copertura dei requisiti | E4: Verifica del grado di copertura funzionale offerta sulla base dell’analisi dei requisiti, delle funzionalità e degli obiettivi richiesti | F4: OK
A5: 002 | B5: Adeguatezza delle funzionalità | C5: Correttezza funzionale | D5: Aderenza ai requisiti | E5: Verifica del grado con cui le funzionalità implementate rispettano i requisiti richiesti | F5: OK
A6: 003 | B6: Adeguatezza delle funzionalità | C6: Appropriatezza funzionale | D6: Conformità alle normative | E6: Verifica l’aderenza delle funzionalità implementate rispetto alle normative pertinenti | F6: OK
A7: 004 | B7: Affidabilità | C7: Robustezza | D7: Robustezza del software | E7: Verifica della capacità del sistema di gestire condizioni non previste dalle specifiche | F7: OK
A8: 005 | B8: Manutenibilità | C8: Analizzabilità | D8: Leggibilità del codice | E8: Verifica della facilità di comprensione del codice, per esempio con riferimento ai nomi utilizzati per i moduli, le funzioni e le variabili, ai commenti e alla dimensione dei moduli e delle funzioni | F8: OK
A9: 006 | B9: Manutenibilità | C9: Analizzabilità | D9: Copertura documentazione tecnica | E9: Verifica del livello di completezza della documentazione tecnica di moduli e funzioni | F9: OK
A10: 007 | B10: Manutenibilità | C10: Analizzabilità | D10: Adeguatezza documentazione tecnica | E10: Verifica della qualità descrittiva della documentazione tecnica di moduli e funzioni | F10: OK
A11: 008 | B11: Manutenibilità | C11: Verificabilità | D11: Completezza dei test | E11: Verifica del grado di copertura del codice sviluppato da parte di test (di varia natura, come test unitari, test di integrazione, test end-to-end, test di accettazione, test di regressione, test di qualità) | F11: OK

Sheet SogliaAccettazione
A1: Intervento | C1: =Copertina!B7 -> MEV 2023_13_PST_PagoPA
A2: Codifica Piano di test | C2: =Copertina!B3 -> SIUT-SIES-CT-1.0-20230327-Allegato_al_piano_Test_2023_13_PST_PagoPA
A3: Verifica Soglia di Accettazione | G3: In Rosso le difformità che hanno superato il numero massimo ammissibile
A4: Classe di rilevanza | B4: Classe di gravità
B5: 1 | C5: 2 | D5: 3 | E5: 4
A6: A | B6: =COUNTIFS(TabellaTest!$H$4:$H$338,1,TabellaTest!$I$4:$I$338,"A",TabellaTest!$J$4:$J$338,"KO") -> 0 | C6: =COUNTIFS(TabellaTest!$H$4:$H$338,2,TabellaTest!$I$4:$I$338,"A",TabellaTest!$J$4:$J$338,"KO") -> 0 | D6: =COUNTIFS(TabellaTest!$H$4:$H$338,3,TabellaTest!$I$4:$I$338,"A",TabellaTest!$J$4:$J$338,"KO") -> 0 | E6: =COUNTIFS(TabellaTest!$H$4:$H$338,4,TabellaTest!$I$4:$I$338,"A",TabellaTest!$J$4:$J$338,"KO") -> 0
A7: B | B7: =COUNTIFS(TabellaTest!$H$4:$H$338,1,TabellaTest!$I$4:$I$338,"B",TabellaTest!$J$4:$J$338,"KO") -> 0 | C7: =COUNTIFS(TabellaTest!$H$4:$H$338,2,TabellaTest!$I$4:$I$338,"B",TabellaTest!$J$4:$J$338,"KO") -> 0 | D7: =COUNTIFS(TabellaTest!$H$4:$H$338,3,TabellaTest!$I$4:$I$338,"B",TabellaTest!$J$4:$J$338,"KO") -> 0 | E7: =COUNTIFS(TabellaTest!$H$4:$H$338,4,TabellaTest!$I$4:$I$338,"B",TabellaTest!$J$4:$J$338,"KO") -> 0
A8: C | B8: =COUNTIFS(TabellaTest!$H$4:$H$338,1,TabellaTest!$I$4:$I$338,"C",TabellaTest!$J$4:$J$338,"KO") -> 0 | C8: =COUNTIFS(TabellaTest!$H$4:$H$338,2,TabellaTest!$I$4:$I$338,"C",TabellaTest!$J$4:$J$338,"KO") -> 0 | D8: =COUNTIFS(TabellaTest!$H$4:$H$338,3,TabellaTest!$I$4:$I$338,"C",TabellaTest!$J$4:$J$338,"KO") -> 0 | E8: =COUNTIFS(TabellaTest!$H$4:$H$338,4,TabellaTest!$I$4:$I$338,"C",TabellaTest!$J$4:$J$338,"KO") -> 0
A14: Numero massimo di difformità ammesse
A15: Classe di rilevanza | B15: Classe di gravità
B16: 1 | C16: 2 | D16: 3 | E16: 4
A17: A | B17: =COUNTIFS(TabellaTest!$H$4:$H$338,1,TabellaTest!$I$4:$I$338,"A") -> 0 | C17: =COUNTIFS(TabellaTest!$H$4:$H$338,2,TabellaTest!$I$4:$I$338,"A") -> 0 | D17: =COUNTIFS(TabellaTest!$H$4:$H$338,3,TabellaTest!$I$4:$I$338,"A") -> 0 | E17: =COUNTIFS(TabellaTest!$H$4:$H$338,4,TabellaTest!$I$4:$I$338,"A") -> 0
A18: B | B18: =COUNTIFS(TabellaTest!$H$4:$H$338,1,TabellaTest!$I$4:$I$338,"B") -> 0 | C18: =COUNTIFS(TabellaTest!$H$4:$H$338,2,TabellaTest!$I$4:$I$338,"B") -> 18 | D18: =COUNTIFS(TabellaTest!$H$4:$H$338,3,TabellaTest!$I$4:$I$338,"B") -> 0 | E18: =COUNTIFS(TabellaTest!$H$4:$H$338,4,TabellaTest!$I$4:$I$338,"B") -> 0
A19: C | B19: =COUNTIFS(TabellaTest!$H$4:$H$338,1,TabellaTest!$I$4:$I$338,"C") -> 0 | C19: =COUNTIFS(TabellaTest!$H$4:$H$338,2,TabellaTest!$I$4:$I$338,"C") -> 0 | D19: =COUNTIFS(TabellaTest!$H$4:$H$338,3,TabellaTest!$I$4:$I$338,"C") -> 3 | E19: =COUNTIFS(TabellaTest!$H$4:$H$338,4,TabellaTest!$I$4:$I$338,"C") -> 0
