Workbook
Name AllUserNames: #REF!
Name AllUserNames: #REF!
Name AllUserNames: #REF!
Name DecisionLastCategory: '[1]Test Decision'!$P$3409
Name DecisionLastSize: '[1]Test Decision'!$Q$3409
Name QACP_Project_Setup: #REF!
Name QACP_Project_Setup: #REF!
Name QACP_Project_Setup: #REF!
Name QACPRiskFactorWeights: #REF!
Name QACPRiskFactorWeights: #REF!
Name QACPRiskFactorWeights: #REF!
Name Raw_Data_In: #REF!
Name Raw_Data_In: #REF!
Name Raw_Data_In: #REF!
Name sfsfd: [2]Users!$A$2:$A$5
Name TempUsers: #REF!
Name TempUsers: #REF!
Name TempUsers: #REF!
Name UserIDs: #REF!
Name UserIDs: #REF!
Name UserIDs: #REF!
Name UserList: #REF!
Name UserList: #REF!
Name UserList: #REF!
Name UserNames: #REF!
Name UserNames: #REF!
Name UserNames: #REF!

Sheet Copertina
B2: Il presente documento è stato redatto con la collaborazione del RTI Engineering Ingegneria Informatica S.p.A. & Sirfin-PA S.r.l. nell’ambito del contratto CIG 73479643B7 per lo “Sviluppo del Sistema Informativo Unitario Telematico, la manutenzione degli attuali sistemi dell’area Penale del Ministero della Giustizia e servizi correlati. Lotto 1”.
B3: Nome del file | C3: SIUT-SIE-CT-1.1-20210531-Allegato_al_piano_test_MEV-Integrazione SIES-ADN (PRE-GOLIVE).xlsx
B4: Piano di test | C4: SIUT-SIE-PT-1.1-20210531-Piano_dei_Test_MEV-Integrazione SIES-ADN (PRE-GOLIVE).pdf
B5: Versione | C5: 1.1
B6: Data | C6: 44347
B7: Intervento | C7: MEV-Integrazione SIES-ADN (PRE-GOLIVE)
B8: Area Applicativa | C8: Penale
B9: Allegato al Piano dei Test

Sheet TabellaTest
A1: Intervento | C1: =Copertina!C7 -> MEV-Integrazione SIES-ADN (PRE-GOLIVE)
A2: Codifica Piano di test | C2: =Copertina!C3 -> SIUT-SIE-CT-1.1-20210531-Allegato_al_piano_test_MEV-Integrazione SIES-ADN (PRE-GOLIVE).xlsx
A3: Codice Appl. | B3: ID. Requisito Padre | C3: Lista Requisiti | D3: ID Caso d'uso | E3: Caso d'uso | F3: ID | G3: Scenario di test | H3: Classe di Gravità (1-4) | I3: Classe di rilevanza (A, B, C) | J3: Esito
A4: SIES | B4: REQ-SIC-003 | C4: REQ-SIC-003 | D4: UC01 | E4: Verifica accesso al sistema SIES dopo associazione utenza ADN e SIES | F4: TF001.UC01 | G4: Verifica: verificare che l'utenza ADN venga associata all' utenza SIES e si acceda correttamente all'applicativo. | H4: 1 | I4: A
A5: SIES | B5: REQ-SIC-003 | C5: REQ-SIC-003 | D5: UC02 | E5: Verifica configurazione utenza ADN e SIES | F5: TF001.UC02 | G5: Verifica: verificare che accedendo all'applicativo SIES tramite utenza ADN è possibile configurare più utenze SIES associate alla stessa utenza ADN | H5: 2 | I5: B
A6: SIES | B6: REQ-SIC-003 | C6: REQ-SIC-003 | D6: UC03 | E6: Verifica di avvenuto trasferimento di un titolo di classe 1 da SIES a NSC | F6: TF002.UC03 | G6: Verifica: verificare che venga trasferito correttamente un titolo di classe 1 dal sistema SIES al sistema NSC | H6: 3 | I6: C
A7: SIES | B7: REQ-SIC-003 | C7: REQ-SIC-003 | D7: UC04 | E7: Verifica di avvenuto trasferimento di un foglio complementare da SIES a NSC | F7: TF001.UC04 | G7: Verifica: verificare che venga trasferito correttamente un foglio complementare dal sistema SIES al sistema NSC | H7: 3 | I7: C
A8: SIES | B8: REQ-SIC-003 | C8: REQ-SIC-003 | D8: UC05 | E8: Verifica accesso al modulo web di interconnessione SIES-NSC | F8: TF002.UC05 | G8: Verifica: verificare che l'accesso al modulo web di interconnessione SIES-NSC avvenga correttamente | H8: 3 | I8: C
A9: SIES | B9: REQ-SIC-003 | C9: REQ-SIC-003 | D9: UC06 | E9: Verifica configurazione utenza ADN e SIES con utenza/password errate | F9: TF001.UC06 | G9: Verifica: verificare il comportamento del sistema dopo accesso tramite utenza ADN quando sia prova a configurare un'utenza/password SIES errate | H9: 2 | I9: B
A10: SIES | B10: REQ-SIC-003 | C10: REQ-SIC-003 | D10: UC07 | E10: Verifica configurazione utenza ADN e SIES con utenza non valida | F10: TF001.UC07 | G10: Verifica: verificare il comportamento del sistema dopo accesso tramite utenza ADN quando sia prova a configurare un'utenza disabilitata | H10: 2 | I10: B
A11: SIES | B11: REQ-SIC-003 | C11: REQ-SIC-003 | D11: UC08 | E11: Verifica creazione nuova utenza SIES | F11: TF001.UC08 | G11: Verifica: Verificare che nel caso sia stata creata una nuova utenza SIES l'utente ADN possa associarla correttamente. | H11: 2 | I11: B
A12: SIES | B12: REQ-SIC-003 | C12: REQ-SIC-003 | D12: UC09 | E12: Verifica modifica utenza SIES | F12: TF001.UC09 | G12: Verifica: Verificare che nel caso sia stata modificata una utenza SIES l'accesso sia congruente alla modifica effettuata. | H12: 2 | I12: B
A13: SIES | B13: REQ-SIC-003 | C13: REQ-SIC-003 | D13: UC10 | E13: Verifica disabilitazione utenza SIES | F13: TF001.UC10 | G13: Verifica: Verificare che nel caso sia stata disabilitata una utenza SIES l'utente ADN non possa più utilizzarla dal giorno successivo. | H13: 4 | I13: C
A14: SIES | B14: REQ-SIC-003 | C14: REQ-SIC-003 | D14: UC11 | E14: Verifica reset password utenza SIES | F14: TF001.UC11 | G14: Verifica: Verificare che nel caso sia stato effettuato il reset password di una utenza SIES, il sistema richieda di associare nuovamente l'utenza ed il cambio password prima di fare accedere al sistema. | H14: 4 | I14: C

Sheet SpecificaTest
A1: Intervento | D1: =Copertina!C7 -> MEV-Integrazione SIES-ADN (PRE-GOLIVE)
A2: Codifica Piano di test | D2: =Copertina!C3 -> SIUT-SIE-CT-1.1-20210531-Allegato_al_piano_test_MEV-Integrazione SIES-ADN (PRE-GOLIVE).xlsx
A3: ID caso di test | B3: Requisito | D3: Caso d'uso | F3: Scenario di test
A4: =TabellaTest!F4 -> TF001.UC01 | B4: =TabellaTest!C4 -> REQ-SIC-003 | D4: =TabellaTest!E4 -> Verifica accesso al sistema SIES dopo associazione utenza ADN e SIES | F4: =TabellaTest!G4 -> Verifica: verificare che l'utenza ADN venga associata all' utenza SIES e si acceda correttamente all'applicativo.
B5: Step | C5: Tipo | D5: Istruzioni (test) | E5: Dati di input (Associated Data) | F5: Risultati attesi (Expected Result) | G5: Esito
B6: P | C6: Attività Preliminari e/o Precondizioni | D6: L’utente si trova sulla pagina di Login del SIES. Il sistema propone la pagina di accesso in cui l’utente sarà tenuto ad inserire le proprie credenziali ADN. | E6: L'utente inserisce le proprie credenziali ADN | F6: il sistema effettua un controllo sulla ‘autenticità’ delle informazioni inserite effettuando una chiamata LDAP sul server ADN di giustizia.
B7: P | C7: Stato Base | D7: Il sistema ridirige l’utente sulla stessa pagina, mostrando una funzione di gestione profilazione delle utenze SIES.
B8: 1 | C8: Azione | D8: L'utente seleziona la procedura di ‘Seleziona/Configura un account’ | F8: Viene visualizzata la pagina per l’inserimento delle credenziali del SIES. | G8: OK
B9: 2 | C9: Azione | D9: L'utente inserisce le proprie credenziali SIES e clicca su Login | F9: IL sistema dopo aver fatto delle verifiche ed associato l'utenza SIC con quella ADN prospetta un messaggio in cui è presente il pulsante Entra e la voce di 'Seleziona/Configura un account' | G9: OK
B10: 3 | C10: Azione | D10: L'utente clicca su Entra
B11: V | C11: Verifica | D11: Verificare che Il sistema visualizzi la welcome page dell’applicazione SIES | G11: OK
A12: =TabellaTest!F5 -> TF001.UC02 | B12: =TabellaTest!C5 -> REQ-SIC-003 | D12: =TabellaTest!E5 -> Verifica configurazione utenza ADN e SIES | F12: =TabellaTest!G5 -> Verifica: verificare che accedendo all'applicativo SIES tramite utenza ADN è possibile configurare più utenze SIES associate alla stessa utenza ADN
B13: Step | C13: Tipo | D13: Istruzioni (test) | E13: Dati di input (Associated Data) | F13: Risultati attesi (Expected Result) | G13: Esito
B14: P | C14: Attività Preliminari e/o Precondizioni | D14: L’utente si trova sulla pagina di Login del SIES. Il sistema propone la pagina di accesso in cui l’utente sarà tenuto ad inserire le proprie credenziali ADN. | E14: L'utente inserisce le proprie credenziali ADN | F14: il sistema effettua un controllo sulla ‘autenticità’ delle informazioni inserite effettuando una chiamata LDAP sul server ADN di giustizia.
B15: P | C15: Stato Base | D15: Il sistema ridirige l’utente sulla stessa pagina, mostrando una funzione di gestione profilazione delle utenze SIES.
B16: 1 | C16: Azione | D16: L’utente ha eseguito in precedenza delle associazioni. Si ritroverà, già configurate, le utenze che utilizza solitamente per l’accesso al SIES. | F16: Viene visualizzata la pagina con le utenze associate con il pulsante Entra ed il link ‘Seleziona/Configura un account’ | G16: OK
B17: 2 | C17: Azione | D17: L'utente seleziona la procedura di ‘Seleziona/Configura un account’ | F17: Viene visualizzata la pagina per l’inserimento delle credenziali del SIES. | G17: OK
B18: 3 | C18: Azione | D18: L'utente inserisce le proprie credenziali SIES e clicca su Login | F18: IL sistema dopo aver fatto delle verifiche ed associato l'utenza SIC con quella ADN prospetta un messaggio in cui è presente il pulsante Entra e la voce di 'Seleziona/Configura un account' | G18: OK
B19: 4 | C19: Azione | D19: L'utente clicca su Entra
B20: V | C20: Verifica | D20: Verificare che Il sistema visualizzi la welcome page dell’applicazione SIES | G20: OK
A21: =TabellaTest!F6 -> TF002.UC03 | B21: =TabellaTest!C6 -> REQ-SIC-003 | D21: =TabellaTest!E6 -> Verifica di avvenuto trasferimento di un titolo di classe 1 da SIES a NSC | F21: =TabellaTest!G6 -> Verifica: verificare che venga trasferito correttamente un titolo di classe 1 dal sistema SIES al sistema NSC
B22: Step | C22: Tipo | D22: Istruzioni (test) | E22: Dati di input (Associated Data) | F22: Risultati attesi (Expected Result) | G22: Esito
B23: P | C23: Attività Preliminari e/o Precondizioni | D23: L'utente effettua l'accesso al sistema SIES | E23: L'utente inserisce le proprie credenziali ADN | F23: il sistema effettua un controllo sulla ‘autenticità’ delle informazioni inserite effettuando una chiamata LDAP sul server ADN di giustizia.
B24: P | C24: Stato Base | D24: Il sistema ridirige l’utente sulla stessa pagina, mostrando una funzione di gestione profilazione delle utenze SIES.
B25: 1 | C25: Azione | D25: L'utente ha già un'utenza SIEP associata alla sua utenza ADN | F25: Viene visualizzata la pagina con l'utenza SIEP associata con il pulsante Entra ed il link ‘Seleziona/Configura un account’ | G25: OK
B26: 2 | C26: Azione | D26: L'utente clicca sul pulsante Entra
B27: 3 | C27: Azione | D27: L'utente si trova nella pagina principale dell'applicazione SIEP.
B28: 4 | C28: Azione | D28: L'utente ricerca e seleziona un procedimento validato | F28: Viene visualizzata la pagina Dettaglio procedimento | G28: OK
B29: 5 | C29: Azione | D29: L'utente clicca sull'icona posta in alto Trasferimento Provvedimento da SIES a NSC | F29: Viene visualizzato un messaggio di Conferma di trasferimento del provvedimento verso il casellario | G29: OK
B30: 6 | C30: Azione | D30: L'utente Conferma il trasferimento
B31: V | C31: Verifica | D31: Verificare che il sistema restituisca un messaggio di trasferimento avvenuto con successo | G31: OK
A32: =TabellaTest!F7 -> TF001.UC04 | B32: =TabellaTest!C7 -> REQ-SIC-003 | D32: =TabellaTest!E7 -> Verifica di avvenuto trasferimento di un foglio complementare da SIES a NSC | F32: =TabellaTest!G7 -> Verifica: verificare che venga trasferito correttamente un foglio complementare dal sistema SIES al sistema NSC
B33: Step | C33: Tipo | D33: Istruzioni (test) | E33: Dati di input (Associated Data) | F33: Risultati attesi (Expected Result) | G33: Esito
B34: P | C34: Attività Preliminari e/o Precondizioni | D34: L'utente effettua l'accesso al sistema SIES | E34: L'utente inserisce le proprie credenziali ADN | F34: il sistema effettua un controllo sulla ‘autenticità’ delle informazioni inserite effettuando una chiamata LDAP sul server ADN di giustizia.
B35: P | C35: Stato Base | D35: Il sistema ridirige l’utente sulla stessa pagina, mostrando una funzione di gestione profilazione delle utenze SIES.
B36: 1 | C36: Azione | D36: L'utente ha già un'utenza SIUS associata ad utenza ADN | F36: Viene visualizzata la pagina con l'utenza SIUS associata con il pulsante Entra ed il link ‘Seleziona/Configura un account’ | G36: OK
B37: 2 | C37: Azione | D37: L'utente clicca sul pulsante Entra
B38: 3 | C38: Azione | D38: L'utente si trova nella pagina principale dell'applicazione SIUS.
B39: 4 | C39: Navigazione | D39: Ricerche e Visualizzazioni » Procedimento per n° SIUS | F39: Visualizzazione pagina Ricerca Procedimento | G39: OK
B40: 5 | C40: Azione | D40: L'utente ricerca e seleziona un procedimento | F40: Viene visualizzata la pagina Dettaglio procedimento | G40: OK
...

Sheet VerificheConformità
A1: Intervento | D1: =Copertina!C7 -> MEV-Integrazione SIES-ADN (PRE-GOLIVE)
A2: Codifica Piano di test | D2: =Copertina!C3 -> SIUT-SIE-CT-1.1-20210531-Allegato_al_piano_test_MEV-Integrazione SIES-ADN (PRE-GOLIVE).xlsx
A3: ID | B3: Tipo Verifica | C3: Attributo | D3: Indicatore | E3: Descrizione tipo Verifica | F3: Esito Verifica Fornitore | G3: Esito Verifica Amministrazione
A4: 001 | B4: Adeguatezza delle funzionalità | C4: Completezza funzionale | D4: Copertura dei requisiti | E4: Verifica del grado di copertura funzionale offerta sulla base dell’analisi dei requisiti, delle funzionalità e degli obiettivi richiesti | F4: OK
A5: 002 | B5: Adeguatezza delle funzionalità | C5: Correttezza funzionale | D5: Aderenza ai requisiti | E5: Verifica del grado con cui le funzionalità implementate rispettano i requisiti richiesti | F5: OK
A6: 003 | B6: Adeguatezza delle funzionalità | C6: Appropriatezza funzionale | D6: Conformità alle normative | E6: Verifica l’aderenza delle funzionalità implementate rispetto alle normative pertinenti | F6: OK
A7: 004 | B7: Affidabilità | C7: Robustezza | D7: Robustezza del software | E7: Verifica della capacità del sistema di gestire condizioni non previste dalle specifiche | F7: OK
A8: 005 | B8: Manutenibilità | C8: Analizzabilità | D8: Leggibilità del codice | E8: Verifica della facilità di comprensione del codice, per esempio con riferimento ai nomi utilizzati per i moduli, le funzioni e le variabili, ai commenti e alla dimensione dei moduli e delle funzioni | F8: OK
A9: 006 | B9: Manutenibilità | C9: Analizzabilità | D9: Copertura documentazione tecnica | E9: Verifica del livello di completezza della documentazione tecnica di moduli e funzioni | F9: OK
A10: 007 | B10: Manutenibilità | C10: Analizzabilità | D10: Adeguatezza documentazione tecnica | E10: Verifica della qualità descrittiva della documentazione tecnica di moduli e funzioni | F10: OK
A11: 008 | B11: Manutenibilità | C11: Verificabilità | D11: Completezza dei test | E11: Verifica del grado di copertura del codice sviluppato da parte di test (di varia natura, come test unitari, test di integrazione, test end-to-end, test di accettazione, test di regressione, test di qualità) | F11: OK

Sheet SogliaAccettazione
A1: Intervento | C1: =Copertina!C7 -> MEV-Integrazione SIES-ADN (PRE-GOLIVE)
A2: Codifica Piano di test | C2: =Copertina!C3 -> SIUT-SIE-CT-1.1-20210531-Allegato_al_piano_test_MEV-Integrazione SIES-ADN (PRE-GOLIVE).xlsx
A3: Verifica Soglia di Accettazione | G3: In Rosso le difformità che hanno superato il numero massimo ammissibile
A4: Classe di rilevanza | B4: Classe di gravità
B5: 1 | C5: 2 | D5: 3 | E5: 4
A6: A | B6: =COUNTIFS(TabellaTest!$H$4:$H$332,1,TabellaTest!$I$4:$I$332,"A",TabellaTest!$J$4:$J$332,"KO") -> 0 | C6: =COUNTIFS(TabellaTest!$H$4:$H$332,2,TabellaTest!$I$4:$I$332,"A",TabellaTest!$J$4:$J$332,"KO") -> 0 | D6: =COUNTIFS(TabellaTest!$H$4:$H$332,3,TabellaTest!$I$4:$I$332,"A",TabellaTest!$J$4:$J$332,"KO") -> 0 | E6: =COUNTIFS(TabellaTest!$H$4:$H$332,4,TabellaTest!$I$4:$I$332,"A",TabellaTest!$J$4:$J$332,"KO") -> 0
A7: B | B7: =COUNTIFS(TabellaTest!$H$4:$H$332,1,TabellaTest!$I$4:$I$332,"B",TabellaTest!$J$4:$J$332,"KO") -> 0 | C7: =COUNTIFS(TabellaTest!$H$4:$H$332,2,TabellaTest!$I$4:$I$332,"B",TabellaTest!$J$4:$J$332,"KO") -> 0 | D7: =COUNTIFS(TabellaTest!$H$4:$H$332,3,TabellaTest!$I$4:$I$332,"B",TabellaTest!$J$4:$J$332,"KO") -> 0 | E7: =COUNTIFS(TabellaTest!$H$4:$H$332,4,TabellaTest!$I$4:$I$332,"B",TabellaTest!$J$4:$J$332,"KO") -> 0
A8: C | B8: =COUNTIFS(TabellaTest!$H$4:$H$332,1,TabellaTest!$I$4:$I$332,"C",TabellaTest!$J$4:$J$332,"KO") -> 0 | C8: =COUNTIFS(TabellaTest!$H$4:$H$332,2,TabellaTest!$I$4:$I$332,"C",TabellaTest!$J$4:$J$332,"KO") -> 0 | D8: =COUNTIFS(TabellaTest!$H$4:$H$332,3,TabellaTest!$I$4:$I$332,"C",TabellaTest!$J$4:$J$332,"KO") -> 0 | E8: =COUNTIFS(TabellaTest!$H$4:$H$332,4,TabellaTest!$I$4:$I$332,"C",TabellaTest!$J$4:$J$332,"KO") -> 0
A14: Numero massimo di difformità ammesse
A15: Classe di rilevanza | B15: Classe di gravità
B16: 1 | C16: 2 | D16: 3 | E16: 4
A17: A | B17: =COUNTIFS(TabellaTest!$H$4:$H$332,1,TabellaTest!$I$4:$I$332,"A") -> 1 | C17: =COUNTIFS(TabellaTest!$H$4:$H$332,2,TabellaTest!$I$4:$I$332,"A") -> 0 | D17: =COUNTIFS(TabellaTest!$H$4:$H$332,3,TabellaTest!$I$4:$I$332,"A") -> 0 | E17: =COUNTIFS(TabellaTest!$H$4:$H$332,4,TabellaTest!$I$4:$I$332,"A") -> 0
A18: B | B18: =COUNTIFS(TabellaTest!$H$4:$H$332,1,TabellaTest!$I$4:$I$332,"B") -> 0 | C18: =COUNTIFS(TabellaTest!$H$4:$H$332,2,TabellaTest!$I$4:$I$332,"B") -> 5 | D18: =COUNTIFS(TabellaTest!$H$4:$H$332,3,TabellaTest!$I$4:$I$332,"B") -> 0 | E18: =COUNTIFS(TabellaTest!$H$4:$H$332,4,TabellaTest!$I$4:$I$332,"B") -> 0
A19: C | B19: =COUNTIFS(TabellaTest!$H$4:$H$332,1,TabellaTest!$I$4:$I$332,"C") -> 0 | C19: =COUNTIFS(TabellaTest!$H$4:$H$332,2,TabellaTest!$I$4:$I$332,"C") -> 0 | D19: =COUNTIFS(TabellaTest!$H$4:$H$332,3,TabellaTest!$I$4:$I$332,"C") -> 3 | E19: =COUNTIFS(TabellaTest!$H$4:$H$332,4,TabellaTest!$I$4:$I$332,"C") -> 2
