Workbook
Name AllUserNames: #REF!
Name AllUserNames: #REF!
Name AllUserNames: #REF!
Name DecisionLastCategory: '[1]Test Decision'!$P$3409
Name DecisionLastCategory: '[1]Test Decision'!$P$3409
Name DecisionLastCategory: '[1]Test Decision'!$P$3409
Name DecisionLastCategory: '[1]Test Decision'!$P$3409
Name DecisionLastCategory: '[1]Test Decision'!$P$3409
Name DecisionLastCategory: '[1]Test Decision'!$P$3409
Name DecisionLastCategory: #N/A
Name DecisionLastCategory: '[2]Test Decision'!$P$3409
Name DecisionLastSize: '[1]Test Decision'!$Q$3409
Name DecisionLastSize: '[1]Test Decision'!$Q$3409
Name DecisionLastSize: '[1]Test Decision'!$Q$3409
Name DecisionLastSize: '[1]Test Decision'!$Q$3409
Name DecisionLastSize: '[1]Test Decision'!$Q$3409
Name DecisionLastSize: '[1]Test Decision'!$Q$3409
Name DecisionLastSize: #N/A
Name DecisionLastSize: '[2]Test Decision'!$Q$3409
Name QACP_Project_Setup: #REF!
Name QACP_Project_Setup: #REF!
Name QACP_Project_Setup: #REF!
Name QACPRiskFactorWeights: #REF!
Name QACPRiskFactorWeights: #REF!
Name QACPRiskFactorWeights: #REF!
Name Raw_Data_In: Raw_Data_In!$A$1:$BN$1
Name Raw_Data_In: #REF!
Name Raw_Data_In: #REF!
Name Raw_Data_In: #REF!
Name sfsfd: [3]Users!$A$2:$A$5
Name sfsfd: [3]Users!$A$2:$A$5
Name sfsfd: [3]Users!$A$2:$A$5
Name sfsfd: [3]Users!$A$2:$A$5
Name sfsfd: [3]Users!$A$2:$A$5
Name sfsfd: [3]Users!$A$2:$A$5
Name sfsfd: [4]Users!$A$2:$A$5
Name TempUsers: #REF!
Name TempUsers: #REF!
Name TempUsers: #REF!
Name UserIDs: #REF!
Name UserIDs: #REF!
Name UserIDs: #REF!
Name UserList: #REF!
Name UserList: #REF!
Name UserList: #REF!
Name UserNames: #REF!
Name UserNames: #REF!
Name UserNames: #REF!

Sheet Raw_Data_In
A1: DisplayID | B1: IsFTR | C1: Level1 | D1: Level2 | E1: Level3 | F1: Level4 | G1: Level5 | H1: Level6 | I1: Level7 | J1: Level8 | K1: Level9 | L1: Level10 | M1: Level11 | N1: Level12 | O1: Assigned_To | P1: Description | Q1: Status | R1: Time_Est | S1: Prior Internal Testing | T1: Prior External Testing | U1: Impact to Release | V1: Maturity of Function | W1: Complexity of Function | X1: Usage Frequency | Y1: Defect Impact | Z1: External Testing Effort | AA1: Custom Factor 1 | AB1: Custom Factor 2 | AC1: Custom Factor 3 | AD1: FTR Risk | AE1: TR Risk | AF1: Total_System_Risk | AG1: Total_Intgr_Risk | AH1: System_Index | AI1: Intgr_Index | AJ1: Cyc1 | AK1: Cyc2 | AL1: Cyc3 | AM1: Cyc4 | AN1: Cyc5 | AO1: Cyc6 | AP1: Cyc7 | AQ1: Cyc8 | AR1: Cyc9 | AS1: Cyc10 | AT1: Cyc11 | AU1: Cyc12 | AV1: Cyc13 | AW1: Cyc14 | AX1: Cyc15 | AY1: Cyc16 | AZ1: Cyc17 | BA1: Cyc18 | BB1: Cyc19 | BC1: Cyc20 | BD1: Project_ID | BE1: Folder_ID | BF1: Req_ID | BG1: Desc1 | BH1: Desc2 | BI1: Desc3 | BJ1: Desc4 | BK1: Desc5 | BL1: Desc6 | BM1: Desc7 | BN1: Desc8

Sheet Descr.fogli lavoro
B1: Descrizione dei fogli di lavoro per la compilazione dell' "Allegato 1 - Tabella dei test" e dell' "Allegato 2 - Specifiche di test" al Piano di test
A3: Questo documento Excel contiene i template da utilizzare per la stesura dell' "Allegato 1 - Tabella dei test" e dell' "Allegato 2 - Specifiche di test" nell'ambito della progettazione dei test in progetti / obiettivi di sviluppo e/o manutenzione software.
A4: Di seguito si riportano le descrizioni dei vari fogli di lavoro.
A5: Per ulteriori istruzioni di compilazione della Tabella di test e delle Specifiche di test, si rimanda ai relativi paragrafi del Piano di test.
A7: Foglio di lavoro | B7: Descrizione
A8: Descr.fogli lavoro (**) | B8: Descrizione dei fogli di lavoro per la compilazione dell' "Allegato 1 - Tabella dei test" e dell' "Allegato 2 - Specifiche di test" al Piano di test
A9: Cop.All.1Tab.test | B9: Copertina dell' "Allegato 1 - Tabella dei test", con le informazioni di riferimento al Piano di test.
A10: All.1Tab.test | B10: "Allegato 1 - Tabella dei test" al Piano di test, contiene le informazioni dei requisiti e funzionalità ed i casi di test ad essi collegati. Contiene inoltre informazioni aggiuntive per la progettazione dei test, quali i livelli di rischio, i cicli di test ecc.
A11: Es.1 (**) | B11: Esempio di Tabella di test compilata.
A12: Cop.All.2Spec.test | B12: Copertina dell' "Allegato 2 - Specifiche di test", con le informazioni di riferimento al Piano di test.
A13: All.2Spec.test | B13: "Allegato 2 - Specifiche di test" al Piano di test, contiene gli script di test sviluppati per ogni singolo caso di test presente nella Tabella dei test.
A14: Es.2 (**) | B14: Esempio di Specifiche di test, con uno script di test compilato e gli altri predisposti (solo intestazione) come dalla tabella dei test (esempio 1)
A15: (*) : Ci si avvarrà di questi fogli di lavoro solo nel caso di utilizzo di macro
A16: (**) : Fogli di lavoro da eliminare nel deliverable

Sheet Descr.macro
B1: Descrizione delle macro
A4: Macro da menu
A5: Get info from (Specifiche di test) | B5: Questa macro ricerca all'interno delle 'specifiche di test' il numero di condizioni di test, la versione e la stima durata presenti per ogni script di test inserito e riporta tale valore sul corrispettivo caso di test nella tabella dei test. In caso di più script di test per lo stesso caso di test, sono riportati i corrispettivi totali (stima durata e n. cond. di test).
A6: Sort (Tabella dei test) | B6: Effettua un sort della tabella dei test, basato sui livelli di scomposizione.
A7: Reset (Tabella dei test) | B7: Elimina tutte le entrate presenti nella tabella dei test e ripropone l'impostazione iniziale.
A8: Reset (Specifiche di test) | B8: Elimina tutte le entrate presenti nella specifica dei test e ripropone l'impostazione iniziale.
A9: Macro da tasti
A10: Insert (CTRL-I) | B10: Inserisce una riga vuota.
A11: Delete (CTRL-E) | B11: Elimina la riga corrente.
A12: Duplicate (CTRL-D) | B12: Duplica la riga corrente mantenendo tutti i valori presenti.
A13: Insert Layout (CTRL-A) | B13: Inserisce il layout dello script di test, come presente nel foglio di lavoro 'layout' nei range definiti in 'Macro Settings'. Utilizzando questa macro si assicura il mantenimento dello standard previsto e la rapidita nella stesura delle informazioni. Modificando i paramentri della macro in 'Macro Settings' e il layout in 'Layout' è possibile utilizzare diversi layout predisposti per specifiche necessità, sempre mantenendo la struttura originale pervista dallo standard. Una volta inserito il layout i campi 'Nome Script di test', 'Descrizione', 'Versione', 'Stima Durata' e 'N. cond. di test' cambiano il colore di sfondo in giallo, per dare evidenza dell'inserimento avvenuto.

Sheet Copertina
B2: Il presente documento è stato redatto con la collaborazione del RTI Engineering Ingegneria Informatica S.p.A - Sirfin-PA nell’ambito del contratto CIG 73479643B7 per lo “SVILUPPO DEL SISTEMA INFORMATIVO UNITARIO TELEMATICO, LA MANUTENZIONE DEGLI ATTUALI SISTEMI DELL’AREA PENALE DEL MINISTERO DELLA GIUSTIZIA E SERVIZI CORRELATI LOTTO 1”
B3: Nome del file | C3: SIUT-SIES-CT-1.0-20251024-Allegato_al_piano_test_SIES_v.12.8.3.0.xlsx
B4: Piano di test | C4: SIUT-SIES-PT-1.0-20251024-Piano_dei_Test_SIES_v.12.8.3.0.docx
B5: Versione | C5: 1.0
B6: Data | C6: 45954
B7: Intervento | C7: SIES v.12.8.3.0
B8: Area Applicativa | C8: Penale
B9: Allegato al Piano dei Test

Sheet TabellaTest
A1: Codice Area | D1: =Copertina!C7 -> SIES v.12.8.3.0 | H1: Codifica Piano di test | J1: =Copertina!C3 -> SIUT-SIES-CT-1.0-20251024-Allegato_al_piano_test_SIES_v.12.8.3.0.xlsx | K1: Versione | L1: =Copertina!C5 -> 1.0
A2: Applicazione | D2: Funzionalità / Requisiti non funzionali | K2: Caso di test
A3: Codice Area | B3: Codice Appl. | C3: ID. Requisito | D3: ID | E3: Primo livello | F3: ID | G3: Primo Livello | H3: Risk (1-5) | I3: ID | J3: Secondo livello | K3: ID | L3: Nome del caso di test | M3: Classe di Gravità (1-4) | N3: Ciclo di test | O3: Stima Durata | P3: Descrizione e note | Q3: Versione | R3: N. cond. di test | S3: Autom. | T3: Classe di rilevanza (A, B, C) | U3: Esito
A4: SIUT | B4: SIES | C4: 202510090125 | F4: =C4 -> 202510090125 | G4: Correzione template -SIEP_PP_PR_AVVPAGAM_PP | I4: SIEP | J4: =CONCATENATE(I4," - ",G4) -> SIEP - Correzione template -SIEP_PP_PR_AVVPAGAM_PP | K4: =CONCATENATE("TF001.",I4) -> TF001.SIEP | L4: Errore nell'impostazione di alcune frasi | P4: Verifica: Verificare che le frasi all'interno del template siano corrette | Q4: 1.0

Sheet Es.1
A1: Progetto / Obiettivo Software | D1: SISP | H1: Codifica Piano di test | J1: CDC-20150009-S14-000-PT-20160129-01-SISP | L1: v.1.0
A2: Applicazione | D2: Funzionalità / Requisiti non funzionali | K2: Caso di test
A3: Codice Area | B3: Codice Appl. | C3: ID. Requisito | D3: ID | E3: Primo livello | F3: ID | G3: Secondo Livello | H3: Risk (1-5) | I3: ID | J3: Terzo livello | K3: ID | L3: Nome del caso di test | M3: Risk (1-5) | N3: Ciclo di test | O3: Stima Durata | P3: Descrizione e note | Q3: Versione | R3: N. cond. di test | S3: Autom. | T3: Classe di rischio
A4: 02 | B4: 28 | C4: REF001 | D4: MF001 | E4: Gestione Progetto | F4: F005 | G4: Dati Anagrafici di un Progetto | H4: 4 | I4: FE025 | J4: Inserimento dati anagrafici | K4: 02FE025-TF01 | L4: Funzionalità generalizzate e funzioni accessorie | M4: 1 | N4: 2 | O4: 15 | P4: Dopo aver attivato dal menu di Navigazione il tasto "Inserimento": - sia presente l'icona di attivazione della maschera di help e, selezionandola, venga mostrata la pagina di help della funzione da cui sia possibile tornare alla maschera chiamante - sia presente il percorso di navigazione della funzione - tutti i campi chiave siano editabiliti -se presenti campi selezionabili da combo, siano valorizzati correttamente -sia presente il bottone di Salva che, attivato comporti il salvataggio dei campi precedentemente inseriti -sia presente il bottone Pulisci i Campi che, per il ripristino del valore di default per i tutti i campi editabili -siano presenti ma non selezionabili tutti i Tab e i sottotab | Q4: 1.0 | R4: 7 | S4: 0 | T4: =IF(H4*M4<1,"Nessuna",IF(H4*M4<=2,"Bassa",IF(H4*M4<=4,"Medio bassa",IF(H4*M4<=9,"Media",IF(H4*M4<=12,"Medio alta","Alta"))))) -> Medio bassa
A5: 02 | B5: 28 | C5: REF001 | D5: MF001 | E5: Gestione Progetto | F5: F005 | G5: Dati Anagrafici di un Progetto | H5: 4 | I5: FE025 | J5: Inserimento dati anagrafici | K5: 02FE025-TF02 | L5: Inserimento corretto dati anagrafici | M5: 5 | N5: 1,2,5 | O5: 45 | P5: Verifica di tutte le condizioni positive di inserimento dati, compresa la verifica utilizzo dei valori di default, obbligatori, controlli formali, consistenza accesso multiutente. | Q5: 1.0 | R5: 8 | S5: 0 | T5: =IF(H5*M5<1,"Nessuna",IF(H5*M5<=2,"Bassa",IF(H5*M5<=4,"Medio bassa",IF(H5*M5<=9,"Media",IF(H5*M5<=12,"Medio alta","Alta"))))) -> Alta
A6: 02 | B6: 28 | C6: REF001 | D6: MF001 | E6: Gestione Progetto | F6: F005 | G6: Dati Anagrafici di un Progetto | H6: 4 | I6: FE025 | J6: Inserimento dati anagrafici | K6: 02FE025-TF03 | L6: Inserimento dati duplicati | M6: 5 | N6: 2 | O6: 20 | P6: Verifica l'inserimento di un dato anagrafico già presente | Q6: 1.0 | R6: 1 | S6: 0 | T6: =IF(H6*M6<1,"Nessuna",IF(H6*M6<=2,"Bassa",IF(H6*M6<=4,"Medio bassa",IF(H6*M6<=9,"Media",IF(H6*M6<=12,"Medio alta","Alta"))))) -> Alta
A7: 02 | B7: 28 | C7: REF001 | D7: MF001 | E7: Gestione Progetto | F7: F005 | G7: Dati Anagrafici di un Progetto | H7: 4 | I7: FE025 | J7: Inserimento dati anagrafici | K7: 02FE025-TF04 | L7: Inserimento dati non validi | M7: 2 | N7: 2 | O7: 20 | P7: Verifica l'inserimento di un dato anagrafico con dati non validi | Q7: 1.0 | R7: 5 | S7: 0 | T7: =IF(H7*M7<1,"Nessuna",IF(H7*M7<=2,"Bassa",IF(H7*M7<=4,"Medio bassa",IF(H7*M7<=9,"Media",IF(H7*M7<=12,"Medio alta","Alta"))))) -> Media
A8: 02 | B8: 28 | C8: REF001 | D8: MF001 | E8: Gestione Progetto | F8: F005 | G8: Dati Anagrafici di un Progetto | H8: 4 | I8: FE025 | J8: Inserimento dati anagrafici | K8: 02FE025-TNF01 | L8: Verifica Accessibilità | M8: 2 | N8: 4 | O8: 20 | P8: Utilizzo della checklist standard di accessibilità | Q8: 1.0 | R8: 6 | S8: 0 | T8: =IF(H8*M8<1,"Nessuna",IF(H8*M8<=2,"Bassa",IF(H8*M8<=4,"Medio bassa",IF(H8*M8<=9,"Media",IF(H8*M8<=12,"Medio alta","Alta"))))) -> Media
A9: 02 | B9: 28 | C9: REF001 | D9: MF001 | E9: Gestione Progetto | F9: F005 | G9: Dati Anagrafici di un Progetto | H9: 4 | I9: FE025 | J9: Inserimento dati anagrafici | K9: 02FE025-TNF02 | L9: Verifica Usabilità | M9: 2 | N9: 4 | O9: 40 | P9: Utilizzo della checklist standard di usabilità | Q9: 1.0 | R9: 6 | S9: 1 | T9: =IF(H9*M9<1,"Nessuna",IF(H9*M9<=2,"Bassa",IF(H9*M9<=4,"Medio bassa",IF(H9*M9<=9,"Media",IF(H9*M9<=12,"Medio alta","Alta"))))) -> Media
A10: 02 | B10: 28 | C10: REF001 | D10: MF001 | E10: Gestione Progetto | F10: F005 | G10: Dati Anagrafici di un Progetto | H10: 4 | K10: 02F005-TI01 | L10: Ricerca - visualizzazione - modifica e cancellazione anagrafica | M10: 4 | N10: 1,3 | O10: 30 | P10: Scenario di test di integrazione tra le funzioni elementari della funzione dati anagrafici, effettuare la ricerca, la visualizzazione, la modifica e la cancellazione | Q10: 1.0 | R10: 3 | S10: 1 | T10: =IF(H10*M10<1,"Nessuna",IF(H10*M10<=2,"Bassa",IF(H10*M10<=4,"Medio bassa",IF(H10*M10<=9,"Media",IF(H10*M10<=12,"Medio alta","Alta"))))) -> Alta
A11: 02 | B11: 28 | C11: REF001 | D11: MF001 | E11: Gestione Progetto | H11: 5 | K11: 02MF001-TI01 | L11: Creazione progetto, inserimento e modifica anagrafica, stampa resoconto. | M11: 4 | N11: 3 | O11: 40 | P11: Scenario di test di integrazione tra le funzioni di gestione dei dati anagrafici del progetto, creazione progetto, inserimento dati anagrafici, modifica e stampa. | Q11: 1.0 | R11: 3 | S11: 1 | T11: =IF(H11*M11<1,"Nessuna",IF(H11*M11<=2,"Bassa",IF(H11*M11<=4,"Medio bassa",IF(H11*M11<=9,"Media",IF(H11*M11<=12,"Medio alta","Alta"))))) -> Alta
A12: 02 | B12: 28 | C12: REF001 | D12: MF001 | E12: Gestione Progetto | F12: CDU001 | G12: Ricerca ed elenco progetti | H12: 3 | I12: CDU001.1 | J12: Scenario Main - ricerca elenco progetti | K12: 02CDU001.1-TI01 | L12: Ricerca - visualizzazione elenco progetti | M12: 5 | N12: 3 | O12: 30 | P12: Scenario di test relativo al flusso main del caso d'uso, prevede la ricerca, visualizzazione dell'elenco dei progetti ricercati, per i quali l'utente risulta abilitato. | Q12: 1.0 | R12: 1 | S12: 0 | T12: =IF(H12*M12<1,"Nessuna",IF(H12*M12<=2,"Bassa",IF(H12*M12<=4,"Medio bassa",IF(H12*M12<=9,"Media",IF(H12*M12<=12,"Medio alta","Alta"))))) -> Alta
A13: 02 | B13: 28 | C13: REF001 | D13: MF001 | E13: Gestione Progetto | F13: CDU001 | G13: Ricerca ed elenco progetti | H13: 3 | I13: CDU001.2 | J13: Scenario Alternativo 1 - ricerca elenco progetti vuota - annulla | K13: 02CDU001.2-TI01 | L13: Ricerca - lista vuota - annulla | M13: 2 | N13: 3 | O13: 30 | P13: Scenario di test relativo allo scenario del caso d'uso derivato dal flusso alternativo di ricderca con esito lista vuota e richiesta di annullamento della ricerca. | Q13: 1.0 | R13: 1 | S13: 1 | T13: =IF(H13*M13<1,"Nessuna",IF(H13*M13<=2,"Bassa",IF(H13*M13<=4,"Medio bassa",IF(H13*M13<=9,"Media",IF(H13*M13<=12,"Medio alta","Alta"))))) -> Media
A14: 02 | B14: 28 | C14: RNF012 | D14: RNF012 | E14: Requisito non funzonale di accessibilità | F14: RNF012.1 | G14: Verifica legge Stanca (4/2004) | H14: 5 | K14: 02RNF012.1-TNF01 | L14: Checklist Accessibilità | M14: 3 | N14: 4 | O14: 60 | P14: Check list per la verifica dei 22 requisiti di accessibilità previsti | Q14: 1.0 | R14: 22 | S14: 1 | T14: =IF(H14*M14<1,"Nessuna",IF(H14*M14<=2,"Bassa",IF(H14*M14<=4,"Medio bassa",IF(H14*M14<=9,"Media",IF(H14*M14<=12,"Medio alta","Alta"))))) -> Alta
A15: 02 | B15: 28 | C15: RNF031 | D15: RNF031 | E15: Requisito non funzonale di Performance | F15: RNF031.1 | G15: Caricamento liste dati entro massimo 20 secondi | H15: 3 | K15: 02RNF031.1-TNF01 | L15: Performance Test su ricerca dati progetto | M15: 4 | N15: 4 | O15: 30 | P15: Effettuare test prestazionali in condizioni di carico sulla base delle analisi di utenza, per verificare il tempo di risposta all'utente nel caricamento della lista dei dati. | Q15: 1.0 | R15: 1 | S15: 0 | T15: =IF(H15*M15<1,"Nessuna",IF(H15*M15<=2,"Bassa",IF(H15*M15<=4,"Medio bassa",IF(H15*M15<=9,"Media",IF(H15*M15<=12,"Medio alta","Alta"))))) -> Medio alta

Sheet Descrizioni
A1: Lvl | B1: Object Type | C1: ID | D1: Name | E1: Risk | F1: Description

Sheet Desc Temp
A1: Lvl | B1: Object Type | C1: ID | D1: Name | E1: Risk | F1: Description

Sheet Cop.All.2ASpec.test
B2: Il presente documento è stato redatto con la collaborazione del RTI Engineering Ingegneria Informatica S.p.A - Sirfin-PA nell’ambito del contratto CIG 73479643B7 per lo “SVILUPPO DEL SISTEMA INFORMATIVO UNITARIO TELEMATICO, LA MANUTENZIONE DEGLI ATTUALI SISTEMI DELL’AREA PENALE DEL MINISTERO DELLA GIUSTIZIA E SERVIZI CORRELATI. LOTTO 1”
B3: <Codifica Piano di test>
B4: Piano di test - <fase>
B5: Ver. x.x
B6: Data: ../../..
B7: <Progetto / Obiettivo Software>
B8: <Area Applicativa>
B9: Allegato 2 - Specifiche di Test

Sheet SpecificaTest
A1: Progetto / Obiettivo Software | D1: =Copertina!C7 -> SIES v.12.8.3.0
A2: Codifica Piano di test | D2: =Copertina!C3 -> SIUT-SIES-CT-1.0-20251024-Allegato_al_piano_test_SIES_v.12.8.3.0.xlsx
A3: ID caso di test | B3: Suffisso Caso di test | C3: Nome Caso di test Tipo Step | E3: Descrizione | G3: Versione | H3: Stima tempo | I3: N.cond. di test | J3: Esito
A4: =TabellaTest!K4 -> TF001.SIEP | B4: =TabellaTest!I4 -> SIEP | C4: =TabellaTest!L4 -> Errore nell'impostazione di alcune frasi | E4: =TabellaTest!P4 -> Verifica: Verificare che le frasi all'interno del template siano corrette | G4: =TabellaTest!Q4 -> 1.0 | J4: OK
B5: Step | C5: Tipo | D5: Istruzioni (test) | E5: Dati di input (Associated Data) | F5: Risultati attesi (Expected Result)
B6: P | C6: Attività Preliminari e/o Precondizioni | D6: L'utente effettua l'accesso al sistema SIES come "Procura della Repubblica Presso il Tribunale Ordinario" | E6: Axxxxx (Procura della Repubblica Presso il Tribunale Ordinario)
B7: P | C7: Stato Base | D7: L'utente si trova nella pagina principale dell'applicazione | E7: Ricercare un fascicolo in cui sia presente un Ordine Esecuzione di Ingiunzione al Pagamento della Pena Pecuniaria "pagata"
B8: 1 | C8: Navigazione | D8: Gestione Altre Sanzioni >> Riscossione Pene Pecuniarie >> Ordine Ingiunzione / Altri Provvedimenti >> Provvedimento Avvenuto Pagamento | F8: Visualizzazione pagina "Gestione Provvedimento Avvenuto Pagamento"
B9: 2 | C9: Azione | D9: L'utente riempe i campi obbligatori e preme il tasto "Conferma" | F9: Visualizzazione pagina "Dettaglio Provvedimento Avvenuto Pagamento Pena Pecuniaria"
B10: 3 | C10: Azione | D10: L'utente preme il tasto "Generazione Stampa" | F10: Produzione del template "SIEP_PP_PR_AVVPAGAM_PP.rtf"
B11: V | C11: Verifica | D11: L'utente ha stampato il template | F11: Il risultato atteso è che le modifiche al template richieste siano state apportate correttamente

Sheet VerificheConformità
A1: Progetto / Obiettivo Software | E1: =Copertina!B7 -> Intervento
A2: Codifica Piano di test | E2: =Copertina!#REF! -> #REF!
A3: ID | B3: Tipo Verifica | C3: Attributo | D3: Indicatore | E3: Descrizione tipo Verifica | F3: Esito Verifica Fornitore | G3: Esito Verifica Amministrazione

Sheet SogliaAccettazione
A1: Progetto / Obiettivo Software | D1: =VerificheConformità!E1 -> Intervento
A2: Codifica Piano di test | D2: =VerificheConformità!E2 -> #REF!
A3: Verifica Soglia di Accettazione | G3: In Rosso le difformità che hanno superato il numero massimo ammissibile
A4: Classe di rilevanza | B4: Classe di gravità
B5: 1 | C5: 2 | D5: 3 | E5: 4
A6: A | B6: =COUNTIFS(TabellaTest!M4:M270,1,TabellaTest!T4:T270,"A",TabellaTest!U4:U270,"KO") -> 0 | C6: =COUNTIFS(TabellaTest!M4:M270,2,TabellaTest!T4:T270,"A",TabellaTest!U4:U270,"KO") -> 0 | D6: =COUNTIFS(TabellaTest!M4:M270,3,TabellaTest!T4:T270,"A",TabellaTest!U4:U270,"KO") -> 0 | E6: =COUNTIFS(TabellaTest!M4:M270,4,TabellaTest!T4:T270,"A",TabellaTest!U4:U270,"KO") -> 0
A7: B | B7: =COUNTIFS(TabellaTest!M4:M270,1,TabellaTest!T4:T270,"B",TabellaTest!U4:U270,"KO") -> 0 | C7: =COUNTIFS(TabellaTest!M4:M270,2,TabellaTest!T4:T270,"B",TabellaTest!U4:U270,"KO") -> 0 | D7: =COUNTIFS(TabellaTest!M4:M270,3,TabellaTest!T4:T270,"B",TabellaTest!U4:U270,"KO") -> 0 | E7: =COUNTIFS(TabellaTest!M4:M270,4,TabellaTest!T4:T270,"B",TabellaTest!U4:U270,"KO") -> 0
A8: C | B8: =COUNTIFS(TabellaTest!M4:M270,1,TabellaTest!T4:T270,"C",TabellaTest!U4:U270,"KO") -> 0 | C8: =COUNTIFS(TabellaTest!M4:M270,2,TabellaTest!T4:T270,"C",TabellaTest!U4:U270,"KO") -> 0 | D8: =COUNTIFS(TabellaTest!M4:M270,3,TabellaTest!T4:T270,"C",TabellaTest!U4:U270,"KO") -> 0 | E8: =COUNTIFS(TabellaTest!M4:M270,4,TabellaTest!T4:T270,"C",TabellaTest!U4:U270,"KO") -> 0
A14: Numero massimo di difformità ammesse
A15: Classe di rilevanza | B15: Classe di gravità
B16: 1 | C16: 2 | D16: 3 | E16: 4
A17: A | B17: =COUNTIFS(TabellaTest!M4:M270,1,TabellaTest!T4:T270,"A") -> 0 | C17: =COUNTIFS(TabellaTest!M4:M270,2,TabellaTest!T4:T270,"A") -> 0 | D17: =COUNTIFS(TabellaTest!M4:M270,3,TabellaTest!T4:T270,"A") -> 0 | E17: =COUNTIFS(TabellaTest!M4:M270,4,TabellaTest!T4:T270,"A") -> 0
A18: B | B18: =COUNTIFS(TabellaTest!M4:M270,1,TabellaTest!T4:T270,"B") -> 0 | C18: =COUNTIFS(TabellaTest!M4:M270,2,TabellaTest!T4:T270,"B") -> 0 | D18: =COUNTIFS(TabellaTest!M4:M270,3,TabellaTest!T4:T270,"B") -> 0 | E18: =COUNTIFS(TabellaTest!M4:M270,4,TabellaTest!T4:T270,"B") -> 0
A19: C | B19: =COUNTIFS(TabellaTest!M4:M270,1,TabellaTest!T4:T270,"C") -> 0 | C19: =COUNTIFS(TabellaTest!M4:M270,2,TabellaTest!T4:T270,"C") -> 0 | D19: =COUNTIFS(TabellaTest!M4:M270,3,TabellaTest!T4:T270,"C") -> 0 | E19: =COUNTIFS(TabellaTest!M4:M270,4,TabellaTest!T4:T270,"C") -> 0

Sheet Automation
A2: Progetto / Obiettivo Software
A3: Codifica Piano di test
A4: ID caso di test | B4: VisualTest | C4: Descrizione | D4: Durata Stimata | E4: QADirector Client | F4: QADirector ToolDomain | G4: TestPartner Project | H4: Stima tempo

Sheet Es.2
A1: Progetto / Obiettivo Software | D1: Gestione Progetto
A2: Codifica Piano di test | D2: ISC-PDT-C26_M_15
A3: ID caso di test | B3: Suffisso Script di test | C3: Nome Script di test | E3: Descrizione | G3: Versione | H3: Stima Durata | I3: N. cond. di test
A4: nome del test | B4: 01 | C4: Nome dello script di test | E4: Descrizione dello script di test (inserire il layout con la macro CTRL-A)
B5: Step | C5: Tipo Step | D5: Istruzioni | E5: Dati di input | F5: Risultati attesi
B6: P | C6: Precondizioni | D6: descrivere le precondizioni | E6: i dati per le precondizioni | F6: la verifica delle precondizioni
B7: P | C7: Stato Base | D7: descrivere il posizionamento dell'applicazione | E7: i dati necessari, esempio login | F7: la verifica dello stato base
B8: 1 | C8: Navigazione | D8: descrivere uno o più pasi di navigazione | E8: i dati se presenti | F8: il risultato al termine della navigazione
B9: 2 | C9: Azione | D9: descrivere la/le azioni dell'utente | E9: i dati utilizzati | F9: i risultati al termine delle azioni
B10: 3 | C10: Navigazione | D10: descrivere uno o più pasi di navigazione | E10: i dati se presenti | F10: il risultato al termine della navigazione
B11: R1 | C11: Riciclo Test | D11: Indicare lo/gli step sul quale effettuare i cambiamenti e descrivere l'obiettivo del ricicli | E11: i nuovi dati | F11: i risultati al termine delle azioni
B12: V | C12: Verifica esterna | D12: descrivere eventuali verifiche esterne da effettuare al termine del test per la verifica dello stesso | E12: i dati se presenti | F12: i risultati al termine delle verifiche
A13: 02FE025-TF02 | B13: 01 | C13: Inserimento corretto dati anagrafici | E13: Verifica di tutte le condizioni positive di inserimento dati, compresa la verifica utilizzo dei valori di default, obbligatori, controlli formali, consistenza accesso multiutente. | G13: 1.0 | H13: 45 | I13: 8
B14: Step | C14: Tipo step | D14: Istruzioni | E14: Dati di input | F14: Risultati attesi
B15: P | C15: Precondizioni | D15: Progetto già definito ma senza informazioni anagrafiche | E15: codice locale progetto : 1234567890
B16: P | C16: Stato Base | D16: Sessione aperta sull'applicazione, sul menu principale del progetto inserito.. Autenticato con utente 'gestore progetto'. | E16: Profilo utente "Gestore Progetto". codice locale progetto : 1234567890 | F16: Applicazione aperta sul menu principale
B17: 1 | C17: Navigazione | D17: menu Progetto - Inserimento - Tab Dati Generali - Sottotab Dati Anagrafici | F17: appare la maschera d'inserimento dati anagrafici
B18: 2 | C18: Azione | D18: Inserire i dati per nuova anagrafica e selezionare bottone "Salva". Il bottone “Salva” consente il salvataggio dei valori impostati nella pagina, nell’entità E004 - Progetti. | E18: Codice locale progetto: 1234567890 Titolo = Codice Tipologia Operazione = 10 Cup Provvisorio = Cup Definitivo = Progetto Strategico = S Codice Procedura = 0001 De Minimis = N | F18: Il sistema mostra un messaggio indicante il mancato inserimento di dati obbligatori (Titolo) in testa alla maschera di Inserimento Dati Anagrafici e imposta i campi valorizzandoli con i dati appena inseriti
B19: 3 | C19: Navigazione | D19: Selezione Tab di uscita, ritorno al menu | F19: appare il menu principale
B20: R1 | C20: Riciclo Script | D20: Rieseguire l'intero script ed inserire i nuovi dati allo step 2. | E20: Codice locale progetto: 1234567890 Titolo = PROGETTO DI TEST Codice Tipologia Operazione = Cup Provvisorio = AA Cup Definitivo = AA Progetto Strategico = S Codice Procedura = 0001 De Minimis = N | F20: Il sistema mostra un messaggio indicante il mancato inserimento di dati obbligatori (codice tipologia operazione) in testa alla maschera di Inserimento Dati Anagrafici e imposta i campi valorizzandoli con i dati appena inseriti
B21: R2 | C21: Riciclo Script | D21: Rieseguire l'intero script ed inserire i nuovi dati allo step 2. | E21: Codice locale progetto: 1234567890 Titolo = PROGETTO DI TEST Codice Tipologia Operazione = 10 Cup Provvisorio = AA Cup Definitivo = AA Progetto Strategico = S Codice Procedura = 0001 De Minimis = N | F21: Il sistema mostra un messaggio indicante i dati salvati correttamente.
B22: R3 | C22: Riciclo Script | D22: Rieseguire l'intero script, i dati che il sistema propone allo step 2 non devono essere modificati. | E22: Codice locale progetto: 1234567890 Titolo = PROGETTO DI TEST Codice Tipologia Operazione = 10 Cup Provvisorio = AA Cup Definitivo = AA Progetto Strategico = S Codice Procedura = 0001 De Minimis = N | F22: Il sistema mostra un messaggio indicante il la mancata modifica e viene ripresentata la stessa schermata con gli stessi dettagli.
B23: R4 | C23: Riciclo Script | D23: Rieseguire l'intero script da due utenze diverse ed inserire i nuovi dati allo step 2. Il primo utente seleziona il bottone salva. Il secondo utente seleziona il bottone salva dopo il primo utente | E23: Codice locale progetto: 1234567890 Titolo = PROGETTO DI TEST Codice Tipologia Operazione = 10 Cup Provvisorio = BB Cup Definitivo = BB Progetto Strategico = S Codice Procedura = 0001 De Minimis = N | F23: Il secondo utente riceve dal sistema il messaggio che i dati sono stati variati da un altro utente, annulla le modifiche e ripresenta i dati correnti.
B24: R5 | C24: Riciclo Script | D24: Rieseguire l'intero script ed inserire i nuovi dati allo step 2. | E24: Codice locale progetto: 1234567890 Titolo = PROGETTO DI TEST Codice Tipologia Operazione = 3 Cup Provvisorio = AA Cup Definitivo = AA Progetto Strategico = S Codice Procedura = 0001 De Minimis = | F24: Il sistema mostra un messaggio indicante il la necessita di valorizzare il campo De Minimis per il codice Tipologia Operazione = 3.
B25: R6 | C25: Riciclo Script | D25: Rieseguire l'intero script ed inserire i nuovi dati allo step 2. | E25: Codice locale progetto: 1234567890 Titolo = PROGETTO DI TEST Codice Tipologia Operazione = 3 Cup Provvisorio = AA Cup Definitivo = AA Progetto Strategico = S Codice Procedura = 0001 De Minimis = S | F25: Il sistema mostra un messaggio indicante i dati salvati correttamente.
B26: R7 | C26: Riciclo Script | D26: Rieseguire l'intero script ed inserire i nuovi dati allo step 2. Selezionare bottone "Rispristina" invece che salva. | E26: Codice locale progetto: 1234567890 Titolo = PROGETTO DI TEST Codice Tipologia Operazione = 10 Cup Provvisorio = AA Cup Definitivo = AA Progetto Strategico = S Codice Procedura = 0001 De Minimis = N | F26: Il sistema ripropone i dati come presenti nell'ultimo salvataggio
B27: V | C27: Verifica esterna | D27: Verificare i dati modificati nell'utlimo riciclo con esito positivo, direttamente sui valori degli attributi dell'occorenza dell'entità E004 - Progetto. | E27: Utilizzare la query "SQL_E004_verifica_dati_anagrafici" consegnata nel piano di test. | F27: Gli attributi per il progetto modificato dal test devono corrispondere all'ultimo riciclo con esito positivo (salvataggio dati).
A28: =Es.1!K6 -> 02FE025-TF03 | B28: 01 | C28: =Es.1!L6 -> Inserimento dati duplicati | E28: Descrizione dello script di test (inserire il layout con la macro CTRL-A)
A29: =Es.1!K7 -> 02FE025-TF04 | B29: 01 | C29: =Es.1!L7 -> Inserimento dati non validi | E29: Descrizione dello script di test (inserire il layout con la macro CTRL-A)
A30: =Es.1!K8 -> 02FE025-TNF01 | B30: 01 | C30: =Es.1!L8 -> Verifica Accessibilità | E30: Descrizione dello script di test (inserire il layout con la macro CTRL-A)
A31: =Es.1!K9 -> 02FE025-TNF02 | B31: 01 | C31: =Es.1!L9 -> Verifica Usabilità | E31: Descrizione dello script di test (inserire il layout con la macro CTRL-A)
A32: =Es.1!K10 -> 02F005-TI01 | B32: 01 | C32: =Es.1!L10 -> Ricerca - visualizzazione - modifica e cancellazione anagrafica | E32: Descrizione dello script di test (inserire il layout con la macro CTRL-A)
A33: =Es.1!K11 -> 02MF001-TI01 | B33: 01 | C33: =Es.1!L11 -> Creazione progetto, inserimento e modifica anagrafica, stampa resoconto. | E33: Descrizione dello script di test (inserire il layout con la macro CTRL-A)
A34: =Es.1!K12 -> 02CDU001.1-TI01 | B34: 01 | C34: =Es.1!L12 -> Ricerca - visualizzazione elenco progetti | E34: Descrizione dello script di test (inserire il layout con la macro CTRL-A)
A35: =Es.1!K13 -> 02CDU001.2-TI01 | B35: 01 | C35: =Es.1!L13 -> Ricerca - lista vuota - annulla | E35: Descrizione dello script di test (inserire il layout con la macro CTRL-A)
A36: =Es.1!K14 -> 02RNF012.1-TNF01 | B36: 01 | C36: =Es.1!L14 -> Checklist Accessibilità | E36: Descrizione dello script di test (inserire il layout con la macro CTRL-A)
A37: =Es.1!K15 -> 02RNF031.1-TNF01 | B37: 01 | C37: =Es.1!L15 -> Performance Test su ricerca dati progetto | E37: Descrizione dello script di test (inserire il layout con la macro CTRL-A)
A38: 02F018-TF04 | B38: 01 | C38: Corretta esecuzione della modifica delle procedure di attivazione | E38: Verifica di tutte le condizioni positive di inserimento dati, compresa la verifica utilizzo dei valori di default | G38: 1 | H38: 10 | I38: 3
B39: Step | C39: Tipo | D39: Istruzioni | E39: Dati di input | F39: Risultati attesi
B40: P | C40: Precondizioni | D40: Precaricare il database, o con funzioni di inserimento, con una procedura di attivazione, senza richieste di predisposione dati | E40: Qualsiasi procedura di attivazione senza richieste di predisposizione dati | F40: Deve risultare presente in base dati almeno 1 procedura di attivazione e non devono essere presenti richieste di predisposizione dati
...

Sheet Settings
A2: Parametri per l'utilizzo delle macro QACenter di gestione della tabella dei test e delle specifiche di test e caricamento nel database far riferimento alle guide operative Compuware per il loro utilizzo
A3: Versione 3.2.4 | B3: Project Settings
B4: ---
A7: ProjectID | B7: ---
A8: FolderID | B8: 1
A9: DefaultUserID | B9: Unassigned
A10: Status | B10: In Progress
A11: Cycles | B11: 10 | E11: (1 to 20)
A13: Level's Max Depth | B13: 4
A14: First Data Row | B14: 4
A15: Risk Model
A18: DisplayID Assembly
A19: Unique Progressive Key
A20: Digit Number | B20: 4
A21: Start From | B21: 0
A22: Counter Gap | B22: 1
A23: Preview | B23: 0000
A25: Level 1 Requirement
A26: Part ID | B26: Value | C26: Type | D26: Length | E26: Delimiter
A27: Element 1 | B27: N/A | C27: Counter | D27: 4 | E27: b
A28: Element 2 | B28: RQ | C28: String | D28: 2 | E28: -
A29: Element 3 | B29: E | C29: column | D29: 22
A30: Element 4 | C30: None
A31: Preview | B31: 0000 RQ- | C31: TOT Length | E31: 30
A33: Level 2 Requirement
A34: Part ID | B34: Value | C34: Type | D34: Length | E34: Delimiter
A35: Element 1 | B35: N/A | C35: Counter | D35: 4 | E35: b
A36: Element 2 | B36: RQ | C36: String | D36: 2 | E36: -
A37: Element 3 | B37: G | C37: Column | D37: 22
A38: Element 4 | C38: None
A39: Preview | B39: 0000 RQ- | C39: TOT Length | E39: 30
A41: Level 3 Requirement
A42: Part ID | B42: Value | C42: Type | D42: Length | E42: Delimiter
A43: Element 1 | B43: N/A | C43: Counter | D43: 4 | E43: b
A44: Element 2 | B44: RQ | C44: String | D44: 2 | E44: -
A45: Element 3 | B45: I | C45: Column | D45: 12 | E45: -
A46: Element 4 | B46: J | C46: Column | D46: 9
A47: Preview | B47: 0000 RQ-- | C47: TOT Length | E47: 30
A49: Test
A50: Part ID | B50: Value | C50: Type | D50: Length | E50: Delimiter
...

Sheet Hidden Settings
A2: DSN Password | B2: testware

Sheet Layout
A1: Layout predefinito Specifiche di Test per macro INSERT LAYOUT (definire il range di celle in Setting - Test Script Layout)
A3: ID caso di test | B3: Suffisso Script di test | C3: Nome Script di test Tipo Step | D3: Istruzioni | E3: Descrizione | F3: Risultati attesi | G3: Versione | H3: Stima tempo | I3: N.cond. di test
A4: TF.001 | B4: 01 | C4: Caso di test 1 | E4: Descrizione | G4: 1
B5: Step | C5: Tipo | D5: Istruzioni (text) | E5: Dati di input (Associated Data) | F5: Risultati attesi (Expected Result)
B6: P | C6: Attività Preliminari e/o Precondizioni | D6: descrivere le precondizioni | E6: i dati per le precondizioni | F6: la verifica delle precondizioni
B7: P | C7: Stato Base | D7: descrivere il posizionamento dell'applicazione | E7: i dati necessari, esempio login | F7: la verifica dello stato base
B8: 1 | C8: Navigazione | D8: descrivere uno o più pasi di navigazione | E8: i dati se presenti | F8: il risultato al termine della navigazione
B9: 2 | C9: Azione | D9: descrivere la/le azioni dell'utente | E9: i dati utilizzati | F9: i risultati al termine delle azioni
B10: 3 | C10: Navigazione | D10: descrivere uno o più pasi di navigazione | E10: i dati se presenti | F10: il risultato al termine della navigazione
B11: R1 | C11: Riciclo Script | D11: Indicare lo/gli step sul quale effettuare i cambiamenti e descrivere l'obiettivo del ricicli | E11: i nuovi dati | F11: i risultati al termine delle azioni
B12: V | C12: Verifica esterna | D12: descrivere eventuali verifiche esterne da effettuare al termine del test per la verifica dello stesso | E12: i dati se presenti | F12: i risultati al termine delle verifiche
A16: TF.001 | B16: 01 | C16: Catena di test 1
B17: Step | C17: Tipo | D17: Istruzioni (text) | E17: Dati di input (Associated Data) | F17: Risultati attesi (Expected Result)
B18: P | C18: Attività Preliminari e/o Precondizioni
B19: P | C19: Stato Base
B20: 1 | C20: Navigazione
B21: 2 | C21: Azione
B22: 3 | C22: Navigazione
B23: 4 | C23: Link Test TF002.1 | D23: Eseguire il test indicato variando le informazioni in input nel passo di inserimento | E23: nuovo Input | F23: nuovo outpiut
B24: 5 | C24: Link Test TF0014.4 | D24: Eseguire il test indicato variando le informazioni in input nel passo di inserimento | E24: in inserimento : nuovo Input In variazione: nuovo input | F24: nuovo outpiut
B25: V | C25: Verifica esterna
A27: TF.001 | B27: 01 | C27: layout Checklist 1
B28: Step | C28: Tipo Step | D28: Istruzioni | E28: Dati di input | F28: Risultati attesi
B29: P | C29: Precondizioni
B30: P | C30: Stato Base
B31: 1 | C31: Navigazione
B32: 2 | C32: Azione
B33: 3 | C33: Navigazione
B34: 4 | C34: Check | D34: Indicare la verifica da eseguire
B35: 5 | C35: Check | D35: Indicare la verifica da eseguire
B36: V | C36: Verifica esterna
A38: Standard variabile
A40: ID caso di test | B40: Suffisso Script di test | C40: Nome Script di test | E40: Descrizione | G40: Versione | H40: Stima tempo | I40: N.cond. di test
A41: TF.001 | B41: 01 | C41: Caso di test 1
B42: Step | C42: Tipo | D42: Istruzioni (text) | E42: Dati di input (Associated Data) | F42: Risultati attesi (Expected Result)
B43: P | C43: Attività Preliminari e/o Precondizioni | D43: assente
B44: P | C44: Stato Base | D44: assente
B45: 1 | C45: Navigazione / Azione
B46: 2 | C46: Navigazione / Azione
B47: 3 | C47: Navigazione / Azione
...

Sheet Validation Log
A1: [All.1Tab.test] Validation Failures

Sheet ReqID_Table
A1: IsFTR | B1: Level | C1: ID | D1: Description | E1: ReqID | F1: Risk | G1: DisplayID

Sheet Temp_Data_Out
A1: Lvl | B1: Display ID | C1: Req Type | D1: Req Name (1) | E1: Req Name (2) | F1: Req Name (3) | G1: Req Name (4) | H1: Req Name (5) | I1: Req Name (6) | J1: Req Name (7) | K1: Req Name (8) | L1: Req Name (9) | M1: Req Name (10) | N1: Req Name (11) | O1: Req Name (12) | P1: Assigned To | Q1: Description | R1: Status | S1: Time Est. | T1: Prior Internal Testing | U1: Prior External Testing | V1: Impact to Release | W1: Maturity of Function | X1: Complexity of Function | Y1: Usage Frequency | Z1: Defect Impact | AA1: External Testing Effort | AB1: Custom Factor 1 | AC1: Custom Factor 2 | AD1: Custom Factor 3 | AE1: Functional Area Risk Weight | AF1: Test Requirement Risk Weight | AG1: System Score | AH1: Intgr. Score | AI1: System Risk | AJ1: Intgr. | AK1: Cyc 1 | AL1: Cyc 2 | AM1: Cyc 3 | AN1: Cyc 4 | AO1: Cyc 5 | AP1: Cyc 6 | AQ1: Cyc 7 | AR1: Cyc 8 | AS1: Cyc 9 | AT1: Cyc 10 | AU1: Cyc 11 | AV1: Cyc 12 | AW1: Cyc 13 | AX1: Cyc 14 | AY1: Cyc 15 | AZ1: Cyc 16 | BA1: Cyc 17 | BB1: Cyc 18 | BC1: Cyc 19 | BD1: Cyc 20 | BE1: Project ID | BF1: Folder ID | BG1: Req. ID | BH1: User ID
